<?xml version="1.0" encoding="utf-8"?>
<!-- This URDF was automatically created by SolidWorks to URDF Exporter! Originally created by Stephen Brawner (brawner@gmail.com) 
     Commit Version: 1.6.0-1-g15f4949  Build Version: 1.6.7594.29634
     For more information, please see http://wiki.ros.org/sw_urdf_exporter -->
<robot
  name="drone">


  <!-- <gazebo>
  <plugin name="gazebo_ros_control" filename="libgazebo_ros_control.so">
    <robotNamespace>/drone</robotNamespace>
    <robotSimType>gazebo_ros_control/DefaultRobotHWSim</robotSimType>
     <robotParam>/robot_description</robotParam>
  </plugin>
  </gazebo>   -->


  <!--Base Link-->
  <link
    name="base_link">
    <inertial>
      <origin
        xyz="0.10398871393486 -0.1 0.112663263182331"
        rpy="0 0 0" />
      <mass
        value="2.26804991176584" />
      <inertia
        ixx="9.97652233502536E-05"
        ixy="1.66898922524467E-07"
        ixz="-1.17703083502394E-05"
        iyy="0.000143209177105433"
        iyz="6.35072021476394E-07"
        izz="5.80634418378303E-05" />
    </inertial>

    <visual>
      <origin
        xyz="0 0 0"
        rpy="0 0 0" />
      <geometry>
        <mesh
          filename="package://drone/meshes/base_link.STL" />
      </geometry>
      <!-- <material
        name="">
        <color
          rgba="0.792156862745098 0.819607843137255 0.933333333333333 1" />
      </material> -->
    </visual>

    <collision>
      <origin
        xyz="0 0 0"
        rpy="0 0 0" />
      <geometry>
        <mesh
          filename="package://drone/meshes/base_link.STL" />
      </geometry>
    </collision>
  </link>

  <gazebo reference = "base_link">
      <material>Gazebo/Black</material>
      </gazebo>


<!--Plugin for simple drone control-->
<!--
<gazebo>
    <plugin name='simple_drone' filename='libplugin_drone.so'>
        <bodyName>base_link</bodyName>
        <imuTopic>/drone/imu</imuTopic>
        <rollpitchProportionalGain>10.0</rollpitchProportionalGain>
        <rollpitchDifferentialGain>5.0</rollpitchDifferentialGain>
        <rollpitchLimit>0.5</rollpitchLimit>
        <yawProportionalGain>2.0</yawProportionalGain>
        <yawDifferentialGain>1.0</yawDifferentialGain>
        <yawLimit>1.5</yawLimit>
        <velocityXYProportionalGain>5.0</velocityXYProportionalGain>
        <velocityXYDifferentialGain>2.3</velocityXYDifferentialGain>
        <velocityXYLimit>2</velocityXYLimit>
        <velocityZProportionalGain>5.0</velocityZProportionalGain>
        <velocityZDifferentialGain>1.0</velocityZDifferentialGain>
        <velocityZLimit>-1</velocityZLimit>
        <positionXYProportionalGain>1.1</positionXYProportionalGain>
        <positionXYDifferentialGain>0.0</positionXYDifferentialGain>
        <positionXYIntegralGain>0.0</positionXYIntegralGain>
        <positionXYLimit>5</positionXYLimit>
        <positionZProportionalGain>1.0</positionZProportionalGain>
        <positionZDifferentialGain>0.2</positionZDifferentialGain>
        <positionZLimit>-1</positionZLimit>
        <maxForce>50</maxForce>
        <motionSmallNoise>0.05</motionSmallNoise>
        <motionDriftNoise>0.03</motionDriftNoise>
        <motionDriftNoiseTime>5.0</motionDriftNoiseTime>
    </plugin>
  </gazebo>
-->
  
<!--Camera Link-->
<link name = "camera_link">
<collision>
<origin xyz = "0 0 0"
              rpy = "0 0 0"/>
<geometry>
<box size="0.007 0.007 0.007"/>
</geometry>
</collision>

<visual>
      <origin xyz="0 0 0" rpy="0 0 0"/>
      <geometry>
	<box size="0.007 0.007 0.007"/>
      </geometry>
      <material name="red"/>
    </visual>

    <inertial>
      <mass value="0.00012" />
      <origin xyz="0 0 0" rpy="0 0 0"/>
      <inertia ixx="1e-6" ixy="0" ixz="0" iyy="1e-6" iyz="0" izz="1e-6" />
    </inertial>
  </link>

  <gazebo reference="camera_link">
  <material>Gazebo/Blue</material>
    <sensor type="camera" name="camera1">
      <update_rate>30.0</update_rate>
      <camera name="head">
        <horizontal_fov>1.3962634</horizontal_fov>
        <image>
          <width>800</width>
          <height>800</height>
          <format>R8G8B8</format>
        </image>
        <clip>
          <near>0.02</near>
          <far>300</far>
        </clip>
        <noise>
          <type>gaussian</type>
          <!-- Noise is sampled independently per pixel on each frame.
               That pixel's noise value is added to each of its color
               channels, which at that point lie in the range [0,1]. -->
          <mean>0.0</mean>
          <stddev>0.007</stddev>
        </noise>
      </camera>
      <plugin name="camera_controller" filename="libgazebo_ros_camera.so">
        <alwaysOn>true</alwaysOn>
        <updateRate>0.0</updateRate>
        <cameraName>drone/camera</cameraName>  <!-- ROS-Topic Name for Camera-->
        <imageTopicName>img_raw</imageTopicName>  <!-- ROS-Topic Name for where Camera publishes images-->
        <cameraInfoTopicName>camera_info</cameraInfoTopicName> <!-- ROS-Topic Name where Camera info is published-->
        <frameName>camera_link_optical</frameName>
        <!-- setting hackBaseline to anything but 0.0 will cause a misalignment
            between the gazebo sensor image and the frame it is supposed to
            be attached to -->
        <hackBaseline>0.0</hackBaseline>
        <distortionK1>0.0</distortionK1>
        <distortionK2>0.0</distortionK2>
        <distortionK3>0.0</distortionK3>
        <distortionT1>0.0</distortionT1>
        <distortionT2>0.0</distortionT2>
        <CxPrime>0</CxPrime>
        <Cx>0.0</Cx>
        <Cy>0.0</Cy>
        <focalLength>0.0</focalLength>
      </plugin>
    </sensor>
  </gazebo>


<!--Camera Joint-->
<joint name="camera_joint" type="fixed">
    <axis xyz="0 0 1" />
    <origin xyz="0.10398871393486 -0.1 0.112663263182331" rpy="0 0 0"/>
    <parent link="base_link"/>
    <child link="camera_link"/>
  </joint>


<!--Canmera Optical Joint-->
<!-- generate an optical frame http://www.ros.org/reps/rep-0103.html#suffix-frames
      so that ros and opencv can operate on the camera frame correctly -->
  <joint name="camera_optical_joint" type="fixed">
    <!-- these values have to be these values otherwise the gazebo camera image
        won't be aligned properly with the frame it is supposedly originating from -->
    <origin xyz="0 0 0" rpy="-1.57079632 0 -1.57079632"/>
    <parent link="camera_link"/>
    <child link="camera_link_optical"/>
  </joint>

  <link name="camera_link_optical">
  </link>

<!--Wing Link 1-->
  <link
    name="prop1">
    <inertial>
      <origin
        xyz="-1.1605E-06 0.023457 -1.5103E-06"
        rpy="0 0 0" />
      <mass
        value="0.0037436" />
      <inertia
        ixx="2.6167E-07"
        ixy="5.3921E-11"
        ixz="-4.2389E-07"
        iyy="1.7889E-06"
        iyz="2.7104E-11"
        izz="1.6769E-06" />
    </inertial>
    <visual>
      <origin
        xyz="0 0 0"
        rpy="0 0 0" />
      <geometry>
        <mesh
          filename="package://drone/meshes/wing_link1.STL" />
      </geometry>
      <!-- <material
        name="">
        <color
          rgba="0.79216 0.81961 0.93333 1" />
      </material> -->
    </visual>
    <collision>
      <origin
        xyz="0 0 0"
        rpy="0 0 0" />
      <geometry>
        <mesh
          filename="package://drone/meshes/wing_link1.STL" />
      </geometry>
    </collision>
  </link>

  <gazebo reference = "prop1">
      <material>Gazebo/Orange</material>
      </gazebo>


<!--Joint 1(Base Link to Wing Link 1)-->
  <joint
    name="prop1_joint"
    type="continuous">
    <origin
      xyz="0.043914 -0.22904 0.12287"
      rpy="1.5708 0 -0.29318" />
    <parent
      link="base_link" />
    <child
      link="prop1" />
    <axis
      xyz="0 1 0" />
    <limit
      lower="0"
      upper="0"
      effort="0"
      velocity="0" />
  </joint>


  <!--Wing Link 2-->
  <link
    name="prop2">
    <inertial>
      <origin
        xyz="-1.1602E-06 0.023457 -1.5102E-06"
        rpy="0 0 0" />
      <mass
        value="0.0037436" />
      <inertia
        ixx="2.6167E-07"
        ixy="5.3922E-11"
        ixz="-4.2389E-07"
        iyy="1.7889E-06"
        iyz="2.71E-11"
        izz="1.6769E-06" />
    </inertial>
    <visual>
      <origin
        xyz="0 0 0"
        rpy="0 0 0" />
      <geometry>
        <mesh
          filename="package://drone/meshes/wing_link2.STL" />
      </geometry>     
      <!-- <material
        name="">
        <color
          rgba="0.79216 0.81961 0.93333 1" />
      </material> -->
    </visual>
    <collision>
      <origin
        xyz="0 0 0"
        rpy="0 0 0" />
      <geometry>
        <mesh
          filename="package://drone/meshes/wing_link2.STL" />
      </geometry>
    </collision>
  </link>

  <gazebo reference = "prop2">
      <material>Gazebo/Orange</material>
      </gazebo>


<!--Joint 2(Base Link to Wing Link 2)-->
  <joint
    name="prop2_joint"
    type="continuous">
    <origin
      xyz="-0.0033195 -0.052423 0.12287"
      rpy="1.5708 0 -1.6567" />
    <parent
      link="base_link" />
    <child
      link="prop2" />
    <axis
      xyz="0 1 0" />
    <limit
      lower="0"
      upper="0"
      effort="0"
      velocity="0" />
  </joint>


  <!--Wing Link 3-->
  <link
    name="prop3">
    <inertial>
      <origin
        xyz="-1.1601E-06 0.023457 -1.5102E-06"
        rpy="0 0 0" />
      <mass
        value="0.0037436" />
      <inertia
        ixx="2.6167E-07"
        ixy="5.3923E-11"
        ixz="-4.2389E-07"
        iyy="1.7889E-06"
        iyz="2.7097E-11"
        izz="1.6769E-06" />
    </inertial>
    <visual>
      <origin
        xyz="0 0 0"
        rpy="0 0 0" />
      <geometry>
        <mesh
          filename="package://drone/meshes/wing_link3.STL" />
      </geometry>    
      <!-- <material
        name="">
        <color
          rgba="0.79216 0.81961 0.93333 1" />
      </material> -->
    </visual>
    <collision>
      <origin
        xyz="0 0 0"
        rpy="0 0 0" />
      <geometry>
        <mesh
          filename="package://drone/meshes/wing_link3.STL" />
      </geometry>
    </collision>
  </link>

  <gazebo reference = "prop3">
      <material>Gazebo/Orange</material>
      </gazebo>


<!--Joint 3(Base Link to Wing Link 3)-->
  <joint
    name="prop3_joint"
    type="continuous">
    <origin
      xyz="0.17791 -0.0047715 0.12287"
      rpy="1.5708 0 -3.0248" />
    <parent
      link="base_link" />
    <child
      link="prop3" />
    <axis
      xyz="0 1 0" />
    <limit
      lower="0"
      upper="0"
      effort="0"
      velocity="0" />
  </joint>


 <!--Wing Link 4--> 
  <link
    name="prop4">
    <inertial>
      <origin
        xyz="-1.163E-06 0.023457 -1.5107E-06"
        rpy="0 0 0" />
      <mass
        value="0.0037436" />
      <inertia
        ixx="2.6167E-07"
        ixy="5.3919E-11"
        ixz="-4.2389E-07"
        iyy="1.7889E-06"
        iyz="2.7123E-11"
        izz="1.6769E-06" />
    </inertial>
    <visual>
      <origin
        xyz="0 0 0"
        rpy="0 0 0" />
      <geometry>
        <mesh
          filename="package://drone/meshes/wing_link4.STL" />
      </geometry>      
      <!-- <material
        name="">
        <color
          rgba="0.79216 0.81961 0.93333 1" />
      </material> -->
    </visual>
    <collision>
      <origin
        xyz="0 0 0"
        rpy="0 0 0" />
      <geometry>
        <mesh
          filename="package://drone/meshes/wing_link4.STL" />
      </geometry>
    </collision>
  </link>

  <gazebo reference = "prop4">
      <material>Gazebo/Orange</material>
      </gazebo>


<!--Joint 4(Base Link to Wing Link 4)-->
  <joint
    name="prop4_joint"
    type="continuous">
    <origin
      xyz="0.22366 -0.18178 0.12287"
      rpy="1.5708 0 0.43793" />
    <parent
      link="base_link" />
    <child
      link="prop4" />
    <axis
      xyz="0 1 0" />
    <limit
      lower="0"
      upper="0"
      effort="0"
      velocity="0" />
  </joint>

<!-- ****************************** Plugins *********************************** -->

<gazebo>
    <!-- <plugin name="imu_plugin" filename="libgazebo_ros_imu.so">
      <updateRate>60</updateRate>
      <alwaysOn>true</alwaysOn>
      <bodyName>imu</bodyName>
      <frameName>imu</frameName>
      <topicName>/drone/imu/data</topicName>
      <serviceName>imu_service</serviceName>
      <gaussianNoise>0.0</gaussianNoise>
      <updateRate>20.0</updateRate>
      <xyzOffset>0 0 0</xyzOffset>
      <rpyOffset>0 0 0</rpyOffset>
    </plugin>

    <plugin name="gps_plugin" filename="libgazebo_ros_gps.so">
      <updateRate>60</updateRate>
      <robotNamespace>drone</robotNamespace>
      <bodyName>gps</bodyName>
      <referenceLatitude>19</referenceLatitude>
      <referenceLongitude>72</referenceLongitude>
      <referenceHeading>0</referenceHeading>
      <referenceAltitude>0</referenceAltitude>
      <topicName>gps</topicName>
      <velocityTopicName>gps_velocity</velocityTopicName>
    </plugin> -->

    <plugin name="gazebo_drone_propulsion" filename="libgazebo_drone_propulsion.so">
      <namespace_model>/drone</namespace_model>
      <activate_pid_control>yes</activate_pid_control>
      <prop_kp> 1 </prop_kp>
      <prop_ki> 0 </prop_ki>
      <prop_kd> 0.0</prop_kd>
      <robotNamespace>drone</robotNamespace>
      <bodyName_1>prop1</bodyName_1>
      <bodyName_2>prop2</bodyName_2>
      <bodyName_3>prop3</bodyName_3>
      <bodyName_4>prop4</bodyName_4>
      <topicName>pwm</topicName>
    </plugin>
  </gazebo>
</robot>
   
  
